<mujoco model='urchin6'>
    <compiler inertiafromgeom='auto' angle='degree' eulerseq='xyz' meshdir='meshes'/>
    <!-- <size nuser_geom='1'/> -->
    <size nuser_actuator='1' nuser_sensor='1' nuser_geom='1'/>
    <option timestep='0.01' iterations='50' solver='PGS' gravity='0 0 -9.81'/>
    <!-- Gravity will change based on the exterr. body we are sim -->
    <!--  -->

    <visual>
    <!-- <quality shadowsize='4096' /> -->


    </visual>


    <default>
        <joint limited='true'/>
        <motor ctrllimited='true'/>
        <geom contype='0' conaffinity='0' condim='1' solref='0.005 1'/>
        <equality solref='0.005 1'/>
        <default class='urchin'>
            <geom material='urchin'/>
        </default>

        <default class='collision'>
            <!-- User parameter for geoms is used to identify collision types -->
            <geom material='collision' contype='1' user='2'/>
        </default>


	</default>


	<asset>
	    <texture type='skybox' builtin='gradient' width='100' height='100' rgb1='0.4 0.6 0.8' rgb2='0 0 0'/>
        <texture name='plane' type='2d' builtin='checker' rgb1='1 1 1' rgb2='1 0.7 0.8' width='100' height='100'/>
        <material name='plane' reflectance='0' texture='plane' texrepeat='1 1' texuniform='true'/>
        <material name='urchin' rgba='0.9 0.5 0.1 1'/>
        <mesh name='body' scale='1.5 1.5 1.5' file='sphere_body.stl'/>
        <mesh name='spine' file='rod_spine_w_point.stl'/>
        <material name='collision' rgba='0.1 0.5 0.9 0'/>
	</asset>

	<worldbody>
		<geom name='floor' pos='0.001 0 0' size='10 10 .125' type='plane' material='plane' conaffinity='15'/>
        <light castshadow='true' directional='true' pos='0 0 3' dir='0 0 -1' diffuse='0.4 0.4 0.4' specular='0 0 0'/>
        <body name='body' pos='0 0 1' childclass='urchin'>
            <camera name='track' pos='0 -3 1' zaxis='0 -1 0.5' mode='track'/>
            <joint type='slide' axis='1 0 0' limited='false'/>
            <joint type='slide' axis='0 1 0' limited='false'/>
            <joint type='slide' axis='0 0 1' limited='false' ref='1.01'/>
            <joint type='ball' limited='false'/>
            <geom type='mesh' mesh='body'/>
            <geom type='mesh' mesh='body' class='collision'/>
            <site name='imu' size='0.01' pos='0 0 0'/>

            <body name='spine1' pos='0 0 -.55' euler='0 0 0'>
                <joint name='spine1' type='slide' range='0 .1' damping='10'/>
                <geom type='mesh' mesh='spine' class='collision'/>
                <geom type='mesh' mesh='spine'/>
            </body>

            <body name='spine2' pos='0 .55 0' euler='90 0 0'>
                <joint name='spine2' type='slide' range='0 .1' damping='10'/>
                <geom type='mesh' mesh='spine' class='collision'/>
                <geom type='mesh' mesh='spine'/>
            </body>

            <body name='spine3' pos='0 0 .55' euler='180 0 0'>
                <joint name='spine3' type='slide' range='0 .1' damping='10'/>
                <geom type='mesh' mesh='spine' class='collision'/>
                <geom type='mesh' mesh='spine'/>
            </body>

            <body name='spine4' pos='0 -.55 0' euler='270 0 0'>
                <joint name='spine4' type='slide' range='0 .1' damping='10'/>
                <geom type='mesh' mesh='spine' class='collision'/>
                <geom type='mesh' mesh='spine'/>
            </body>

            <body name='spine5' pos='-.55 0 0' euler='0 90 0'>
                <joint name='spine5' type='slide' range='0 .1' damping='10'/>
                <geom type='mesh' mesh='spine' class='collision'/>
                <geom type='mesh' mesh='spine'/>
            </body>

            <body name='spine6' pos='.55 0 0' euler='0 270 0'>
                <joint name='spine6' type='slide' range='0 .1' damping='10'/>
                <geom type='mesh' mesh='spine' class='collision'/>
                <geom type='mesh' mesh='spine'/>
            </body>


        </body>
	</worldbody>

    <actuator>
        <position name='spine1'  joint='spine1' kp='100' ctrlrange='-100 100'/>
        <position name='spine2'  joint='spine2' kp='100' ctrlrange='-100 100'/>
        <position name='spine3'  joint='spine3' kp='100' ctrlrange='-100 100'/>
        <position name='spine4'  joint='spine4' kp='100' ctrlrange='-100 100'/>
        <position name='spine5'  joint='spine5' kp='100' ctrlrange='-100 100'/>
        <position name='spine6'  joint='spine6' kp='100' ctrlrange='-100 100'/>


    </actuator>

    <sensor>
        <framequat     name='body-orientation' objtype='site' objname='imu'/>
        <gyro          name='body-angular-velocity'    site='imu' noise='5e-4' cutoff='34.9'/>
        <accelerometer name='body-linear-acceleration' site='imu' noise='1e-2' cutoff='157'/>
        <magnetometer  name='body-magnetometer'        site='imu'/>
    </sensor>

</mujoco>
